# 异常的捕获及处理

## 异常对程序的影响

异常指导致程序中断执行的指令流。

正常程序：
```java
public class JavaDemo {
	public static void main(String args[]) {
		System.out.println("【1】****程序开始执行*******") ;
		System.out.println("【2】****数学计算：" + (10/2) + "*******") ;
		System.out.println("【3】****程序执行完毕*******") ;
	}
}
```


异常程序：
```java
public class JavaDemo {
	public static void main(String args[]) {
		System.out.println("【1】****程序开始执行*******") ;
		System.out.println("【2】****数学计算：" + (10/0) + "*******") ;
		System.out.println("【3】****程序执行完毕*******") ;
	}
}
```
由于 0 做除数，程序执行中断。

为保证程序出现非致命错误时可以执行完毕，引入异常处理机制。


## 处理异常

JAVA 中异常处理，可以使用：try,catch,finally 关键字，基本处理结构如下：
```java
try {
	//可能出现异常的语句
} [catch (异常类型 异常对象) {
	//异常处理
} catch (异常类型 异常对象) {
	//异常处理
} catch (异常类型 异常对象) {
	//异常处理
} ... ] [finally {
	//无论异常是否处理都要执行 ;
}]
```

可用格式组合：
* try ... catch
* try ... catch ... finally
* try ... finally

处理异常
```java
public class JavaDemo {
	public static void main(String args[]) {
		System.out.println("【1】****程序开始执行*******") ;
		try {
			System.out.println("【2】****数学计算：" + (10/0) + "*******") ;
		} catch (ArithmeticException e) {
			System.out.println(e) ; //处理异常
		}		
		System.out.println("【3】****程序执行完毕*******") ;
	}
}
```

此时打印的异常信息并不完整，可以使用 printStackTrace() 方法获取完整异常信息。

获取完整异常信息：
```java
public class JavaDemo {
	public static void main(String args[]) {
		System.out.println("【1】****程序开始执行*******") ;
		try {
			System.out.println("【2】****数学计算：" + (10/0) + "*******") ;
		} catch (ArithmeticException e) {
			e.printStackTrace() ;
		}		
		System.out.println("【3】****程序执行完毕*******") ;
	}
}
```

异常处理可以追加 finally 程序块，表示异常处理后的出口，无论是都异常都执行。

使用 finally 语句：
```java
public class JavaDemo {
	public static void main(String args[]) {
		System.out.println("【1】****程序开始执行*******") ;
		try {
			System.out.println("【2】****数学计算：" + (10/0) + "*******") ;
		} catch (ArithmeticException e) {
			e.printStackTrace() ;
		} finally {
			System.out.println("【F】无论是否异常都执行") ;
		}		
		System.out.println("【3】****程序执行完毕*******") ;
	}
}
```

无论有无异常都执行 finally .



## 处理多个异常

```java
public class JavaDemo {
	public static void main(String args[]) {
		System.out.println("【1】****程序开始执行*******") ;
		try {
			int x = Integer.parseInt(args[0]) ;
			int y = Integer.parseInt(args[1]) ;
			System.out.println("【2】****数学计算：" + (x / y) + "*******") ;
		} catch (ArithmeticException e) {
			e.printStackTrace() ;
		} finally {
			System.out.println("【F】无论是否异常都执行") ;
		}		
		System.out.println("【3】****程序执行完毕*******") ;
	}
}
```

此时程序可能产生 3 类异常：
* （java JavaDemo）【未处理】程序执行时未输入初始化参数：java.lang.ArrayIndexOutOfBoundsException;
	* 程序执行结果：【1】****程序开始执行*******
					【F】无论是否异常都执行
					Exception in thread "main" java.lang.ArrayIndexOutOfBoundsException: Index 0 out of bounds for length 0 at JavaDemo.main(JavaDemo.java:5)
* （java JavaDemo a b）【未处理】输入的数据不是数字：java.lang.NumberFormatException;
	* 程序执行结果：【1】****程序开始执行*******
                    【F】无论是否异常都执行
					Exception in thread "main" java.lang.NumberFormatException: For input string: "a"
			        at java.base/java.lang.NumberFormatException.forInputString(NumberFormatException.java:65)
			        at java.base/java.lang.Integer.parseInt(Integer.java:652)
			        at java.base/java.lang.Integer.parseInt(Integer.java:770)
			        at JavaDemo.main(JavaDemo.java:5)
* （java JavaDemo 10 0）【已处理】被除数为0:java.lang.ArithmeticException.
	* 程序执行结果：【1】****程序开始执行*******
					java.lang.ArithmeticException: / by zero at JavaDemo.main(JavaDemo.java:7)
					【F】无论是否异常都执行
					【3】****程序执行完毕*******

即使进行了异常处理，但没有进行正确的异常捕获，程序也会异常中断，finally 关键字后的语句会正常输出。



## 异常处理流程

![JAVA 异常处理流程]()

1. 程序运行中才会产生异常，程序执行中产生了异常对象后将自动进行指定类型的异常类对象实例化处理。

2. 若此时程序中未提供有异常处理支持，则会采用 JVM 默认异常处理方式，首先进行异常处理打印，之后直接退出当前程序。

3. 若存在异常处理，则产生的异常类实例化对象会被 try 语句捕获。

4. try 捕获到异常之后与其匹配的 catch 中的异常类进行依次比对，若与 catch 相匹配则用此 catch 进行异常处理，若未匹配成功则异常没有处理。

5. 不管异常是否处理最终都将执行 finally 代码，执行完 finally 后进一步判断当前异常是否处理，处理则继续执行后续语句，未处理则交由 JVM 进行默认处理。

Class ArithmeticException：
* java.lang.Object
	* java.lang.Throwable
		* java.lang.Exception
			* java.lang.RuntimeException
				* java.lang.ArithmeticException

Class ArrayIndexOutOfBoundsException：
* java.lang.Object
	* java.lang.Throwable
		* java.lang.Exception
			* java.lang.RuntimeException
				* java.lang.IndexOutOfBoundsException
					* java.lang.ArrayIndexOutOfBoundsException

程序中可以处理的异常的最大类型是 Throwable，提供有两个字类：
* Error: 程序还未执行时出现的错误，开发者无法处理；
* Exception: 程序中出现的异常，开发者可以处理。

```java
public class JavaDemo {
	public static void main(String args[]) {
		System.out.println("【1】****程序开始执行*******") ;
		try {
			int x = Integer.parseInt(args[0]) ;
			int y = Integer.parseInt(args[1]) ;
			System.out.println("【2】****数学计算：" + (x / y) + "*******") ;
		} catch (Exception e) {
			e.printStackTrace() ;
		} finally {
			System.out.println("【F】无论是否异常都执行") ;
		}		
		System.out.println("【3】****程序执行完毕*******") ;
	}
}
```

Exception 是所有异常最大类，能处理所有异常，但对于具体异常无法进行区分，使用时应综合考虑。

**日后进行多异常同时处理时，应把捕获范围大的异常放在捕获范围小的异常之后**。




## throws 关键字

使用 throws 关键字在方法声明中可以对异常进行标注。

```java
class MyMath {
	//代码执行可能会产生异常，可调用处处理
	public static int div(int x, int y) throws Exception {
		return x / y ;
	}
}
public class JavaDemo {
	public static void main(String args[]) {
		try {
			System.out.println(MyMath.div(10,2)) ; //改为System.out.println(MyMath.div(10,0))也可正常执行
		} catch (Exception e) {
			e.printStackTrace() ;
		}
	}
}
```

在主方法上继续抛出异常：
```java
class MyMath {
	//代码执行可能会产生异常，可调用处处理
	public static int div(int x, int y) throws Exception {
		return x / y ;
	}
}
public class JavaDemo {
	public static void main(String args[]) throws Exception {
		System.out.println(MyMath.div(10,0)) ;
	}
}
```


## throw 关键字

throw 关键字表示手工进行异常抛出，即手工产生实例化对象并进行异常抛出。

```java
public class JavaDemo {
	public static void main(String args[]) {
		throw new Exception("自己产生的异常") ;
	}
}
```

```java
public class JavaDemo {
	public static void main(String args[]) {
		try { //异常对象不再由系统生成，而是手工定义
			throw new Exception("自己产生的异常") ;
		} catch (Exception e) {
			e.printStackTrace() ;
		}		
	}
}
```

throw 与 throws 的区别：
* throw：在代码块中使用，主要是手工进行异常对象处理；
* throws: 在方法定义上使用，表示将此方法中可能产生的异常明确告诉调用处，由调用处进行处理。


## 异常处理模型

异常处理时，try/catch/finally/throw/throws 等关键字往往会一起使用。

定义可以实现除法计算的方法：
* 在进行数学计算开始与结束时进行信息提示；
* 在计算过程中产生异常，则交由调用处进行处理。

```java
class MyMath {
	//异常交给调用处处理，须在方法上使用throws 
	public static int div(int x, int y) throws Exception {
		int temp = 0 ;
		System.out.println("****start*********") ;
		temp =  x / y ;
		System.out.println("*****end*****") ;
		return temp ;
	}
}
public class JavaDemo {
	public static void main(String args[]) throws Exception {
		try {
			System.out.println(MyMath.div(10,2)) ;
		} catch (Exception e) {
			e.printStackTrace() ;
		}		
	}
}
```

此时若将 div(10,2) 改为 div(10,0) 将出现异常，结束语句不出现。

应改为：
```java
class MyMath {
	//异常交给调用处处理，须在方法上使用throws 
	public static int div(int x, int y) throws Exception {
		int temp = 0 ;
		System.out.println("****start*********") ;
		try {
			temp =  x / y ;
		} catch (Exception e) {	
			throw e ; //向上抛出异常		
		} finally {
			System.out.println("*****end*****") ;
		}
		return temp ;
	}
}
public class JavaDemo {
	public static void main(String args[]) throws Exception {
		try {
			System.out.println(MyMath.div(10,0)) ;
		} catch (Exception e) {
			e.printStackTrace() ;
		}		
	}
}
```

catch 可以省略：
```java
class MyMath {
	//异常交给调用处处理，须在方法上使用throws 
	public static int div(int x, int y) throws Exception {
		int temp = 0 ;
		System.out.println("****start*********") ;
		try {
			temp =  x / y ;
		} finally {
			System.out.println("*****end*****") ;
		}
		return temp ;
	}
}
public class JavaDemo {
	public static void main(String args[]) throws Exception {
		try {
			System.out.println(MyMath.div(10,0)) ;
		} catch (Exception e) {
			e.printStackTrace() ;
		}		
	}
}
```


## RuntimeException

```java
public class JavaDemo {
	public static void main(String args[]) throws Exception {
		int num = Integer.parseInt("123") ;
		System.out.println(num) ;		
	}
}
```

parseInt 方法：
```java
public static int parseInt​(String s) throws NumberFormatException
```

Class NumberFormatException：
* java.lang.Object
	* java.lang.Throwable
		* java.lang.Exception
			* java.lang.RuntimeException
				* java.lang.IllegalArgumentException
					* java.lang.NumberFormatException

考虑到编写方便，提供灵活可选的异常处理父类 RuntimeException， 该类的子类不需要进行强制性处理。


RuntimeException 与 Exception 的区别：
* RuntimeException 是 Exception 的子类；
* RuntimeException 标注的异常不需要进行强制性处理，Exception 异常则需要强制性处理。
* 常见 RuntimeException：NumberFormatException，ClassCastException，NullPointerException


## 自定义异常类

对于自定义异常，有两种实现方案：继承 Exception 或继承 RuntimeException.

继承 Exception：
```java
class BombException extends Exception {
	public BombException(String msg) {
		super(msg) ;
	}
}
class Food {
	public static void eat(int num) throws BombException {
		if (num > 10) {
			throw new BombException("食物过多") ;
		} else {
			System.out.println("使劲吃") ;
		}
	}
}
public class JavaDemo {
	public static void main(String args[]) {
		Food.eat(11) ;		
	}
}
```

继承 RuntimeException:
```java
class BombException extends RuntimeException {
	public BombException(String msg) {
		super(msg) ;
	}
}
class Food {
	public static void eat(int num) throws BombException {
		if (num > 10) {
			throw new BombException("食物过多") ;
		} else {
			System.out.println("使劲吃") ;
		}
	}
}
public class JavaDemo {
	public static void main(String args[]) throws Exception {
		Food.eat(11) ;		
	}
}
```

## assert 断言

从 JDK 1.4 开始追加有断言（assert）功能。断言不一定正确，不能影响程序正常执行。

使用断言：
```java
public class JavaDemo {
	public static void main(String args[]) {
		int x = 10 ;
		// 中间会经过许多x变量的操作
		assert x == 100 : "x 的内容不是100" ;
		System.out.println(x) ;
	}
}
```

若想执行断言，须在程序执行时加入参数：
```java
java -ea JavaDemo
```
执行后将提示错误。

JAVA 中没有将断言设置为必须执行的步骤，需特定环境下才可以开启。

